<?xml version="1.0"?>
<robot xmlns:xacro="http://www.ros.org/wiki/xacro">

    <xacro:include filename="inertial_macros.xacro" />
    <!-- the coordinate plane is x (left right) y (forward back) with z describing height-->
    <material name="white">
        <color rgba="1 1 1 1" />
    </material>

    <material name="orange">
        <color rgba="1 0.3 0.1 1" />
    </material>

    <material name="blue">
        <color rgba="0.2 0.2 1 1" />
    </material>

    <material name="black">
        <color rgba="0 0 0 1" />
    </material>

    <link name="base_link">
        <!--  Better to have the base link to be in the center of the robot and define everything as
        an offset against-->

    </link>

    <!--  CHASSIS LINK-->
    <joint name="chassis_joint" type="fixed">
        <parent link="base_link" />
        <child link="chassis" />
        <origin xyz="-0.1 0 0" />
        <!-- This puts the chassis joint right behind the base link by 0.1 meters-->

    </joint>
    <link name="chassis">
        <visual>
            <origin xyz="0.15 0  0.075" /> <!-- The offset needed to spawn the box with the chassis
            origin shifted to the right hand side mid point z bottomed -->
            <!--
            https://cdn.discordapp.com/attachments/746279918660223118/1286630161143435294/8xKngfC.png?ex=66ee9b36&is=66ed49b6&hm=33bf857073db0385533b2cc3de868707f4b85eaff8bf781fe515346e5d3d1e8b&-->
            <geometry>
                <box size="0.3 0.3 0.15" /> <!--  By default this box is going to spawn at the center
                of the chassis origin. To fix this we need to offset it-->
            </geometry>
            <material name="white" />
        </visual>
        <collision>
            <origin xyz="0.15 0  0.075" />
            <geometry>
                <box size="0.3 0.3 0.15" />
            </geometry>
        </collision>
        <xacro:inertial_box mass="0.5" x="0.3" y="0.3" z="0.15">
            <origin xyz="0.15  0 0.075" rpy="0 0 0" />
        </xacro:inertial_box>
    </link>

    <gazebo reference="chassis">
        <material>Gazebo/White</material>
    </gazebo>
    <!--  LEFT WHEEL LINK-->
    <joint name="left_wheel_joint" type="continuous">
        <parent link="base_link" />
        <child link="left_wheel" />
        <!-- so the wheel is not in the center of the robot, but instead it is offsetted to the
        side-->
        <!-- The wheel also spawns facing up , we want to roll it so that it faces the sides-->
        <origin xyz="0 0.175 0" rpy="-${pi/2} 0 0" /> <!-- rpy = roll(spinning on zy) pitch (spinning
        on xz) yaw (spinning xy (like the wheel turning in a car))-->
        <axis xyz="0 0 1" /> <!-- This tells us the axis the wheel spins when provided a positive
        movement. We want it to spin on the spot  so the axis is z  -->
        <!-- The reason why its positive is because we are rolling the wheel down like pushing it
        off a staircase. Doing so makes the z axis point outward , y axis point down and x point
        forward. A negative change in the z spin would cause x z to rotate positively-->
    </joint>
    <link name="left_wheel">
        <visual>
            <geometry>
                <cylinder radius="0.05" length="0.04" />
            </geometry>

            <!--
            https://cdn.discordapp.com/attachments/746279918660223118/1286631486769991716/OP6gkRy.png?ex=66ee9c72&is=66ed4af2&hm=9070930dcc23861253419db2aecd3462b2585c8a15c291ca9aa4ea317b46cf1e&-->
            <material name="blue" />
        </visual>
        <collision>
            <geometry>
                <cylinder radius="0.05" length="0.04" />
            </geometry>
        </collision>
        <xacro:inertial_cylinder mass="0.1" length="0.04" radius="0.05">
            <origin xyz="0 0 0" rpy="0 0 0" />
        </xacro:inertial_cylinder>
    </link>
    <gazebo reference="left_wheel">
        <material>Gazebo/Blue</material>
    </gazebo>

    <!--  RIGHT WHEEL LINK-->
    <joint name="right_wheel_joint" type="continuous">
        <parent link="base_link" />
        <child link="right_wheel" />
        <!-- so the wheel is not in the center of the robot, but instead it is offsetted to the
        side-->
        <!-- The wheel also spawns facing up , we want to roll it so that it faces the sides-->
        <origin xyz="0 -0.175 0" rpy="${pi/2} 0 0" /> <!-- rpy = roll(spinning on zy) pitch (spinning
        on xz) yaw (spinning xy (like the wheel turning in a car))-->
        <axis xyz="0 0 -1" /> <!-- This tells us the axis the wheel spins when provided a positive
        movement. We want it to spin on the spot  so the axis is z  negative -->
        <!-- The reason why its negative is because we are rolling the wheel from spawn onto the
        right hand side (like making it stand up), This means the initial z position is point
        outward, y axis point UP and x points forward. Due to the inverted y, spinning z to cause a
        positive rotation would imply a negative axis spin-->

    </joint>
    <link name="right_wheel">
        <visual>
            <geometry>
                <cylinder radius="0.05" length="0.04" />
            </geometry>

            <!--
            https://cdn.discordapp.com/attachments/746279918660223118/1286631486769991716/OP6gkRy.png?ex=66ee9c72&is=66ed4af2&hm=9070930dcc23861253419db2aecd3462b2585c8a15c291ca9aa4ea317b46cf1e&-->
            <material name="blue" />
        </visual>
        <collision>
            <geometry>
                <cylinder radius="0.05" length="0.04" />
            </geometry>
        </collision>
        <xacro:inertial_cylinder mass="0.1" length="0.04" radius="0.05">
            <origin xyz="0 0 0" rpy="0 0 0" />
        </xacro:inertial_cylinder>
    </link>
    <gazebo reference="right_wheel">
        <material>Gazebo/Blue</material>
    </gazebo>
    <!-- CASTER WHEEL LINK-->
    <joint name="caster_wheel_joint" type="fixed">
        <parent link="chassis" />
        <child link="caster_wheel" /> <!-- This sits at the back-->
        <origin xyz="0.24 0 0" />

    </joint>

    <link name="caster_wheel">
        <visual>
            <geometry>
                <sphere radius="0.05" />
            </geometry>
            <material name="black" />

        </visual>
        <collision>
            <geometry>
                <sphere radius="0.05" />
            </geometry>
        </collision>
        <xacro:inertial_sphere mass="0.1" radius="0.05">
            <origin xyz="0 0 0" rpy="0 0 0" />
        </xacro:inertial_sphere>
    </link>
    <gazebo reference="caster_wheel">
        <material>Gazebo/Black</material>
        <mu1 value="0.001" /> <!--  This makes the caster wheel nearly frictionless-->
        <mu2 value="0.001" />
    </gazebo>
</robot>